Workbook

Sheet INVOICE
G1: INAE1352/26
A2: Russian express | C2: Ekaterina.Akinina@r-express.ru | E2: Operator: | G2: booking@adatours.com
A3: REF : | B3: Nina Matalasova Valeriia Polozova
A4: Deadline for payment: | B4: Prepayment till: | D4: Land Services | E4: Refundable prior to 20 days to arrival cancellation
B5: Full payment till: | C5: 08.04.2026 | D5: Hotels | E5: Penalties according to hotel's policy
A6: IMPORTANT: All bank charges should be covered by ordering customer | D6: Flights | E6: Non refundable
A7: Hotels
A8: Date | B8: Hotel Name | C8: Category | D8: Meal Plan | E8: City | F8: Usd | G8: Room's | H8: Nights | I8: Subtotal
A9: Check In: 08.05.2026 Check Out: 10.05.2026 | B9: Evolucao Ecolodge | C9: SGL Cahlet | D9: Full board | E9: Manaus | F9: Incl. | G9: 2 | H9: 2 | I9: Incl.
A23: Services
A24: Date | B24: Services | E24: City | F24: Usd | G24: Paxs | H24: Way(s) | I24: Subtotal
A25: 08-10.05.2026 | B25: Evolucao Ecolodge Pakage 3d2n included transfers and tours in group with English guide, Meeting of the waters, inc Pink dolphins swimming | E25: Manaus | F25: Incl. | G25: 2 | H25: 1 | I25: =1300*2 -> 2600
A26: Total price | I26: =I25 -> 2600
A27: Total to be Paid | I27: =I26 -> 2600
A29: The money can be transfered to: Beneficiary Bank : BANK OF AMERICA Bank address: 801 E. HALLANDALE BEACH BLVD. FLORIDA , 3309. SWIFT: BOFAUS3N BANK ACCOUNT : 898092533700 ABA : 026009593 | F29: Beneficiary: VIPDELUXETRAVEL LLC Beneficiary Address : 200 S. PARK RD. SUITE 301. HOLLYWOOD. FL 33021

Sheet VOUCHERS HTLS
B3: VOUCHER NUMBER | C3: =TRIM(INVOICE!$G$1) -> INAE1352/26
B5: CLIENT NAME | C5: =TRIM(INVOICE!$B$3) -> Nina Matalasova Valeriia Polozova
B6: CITY | C6: =TRIM(INVOICE!E9) -> Manaus
B7: HOTEL | C7: =TRIM(INVOICE!B9) -> Evolucao Ecolodge
B8: CATEGORY ROOM | C8: =TRIM(INVOICE!C9) -> SGL Cahlet | D8: Qtd | E8: =TRIM(INVOICE!G9) -> 2
B9: MEAL PLAN | C9: =TRIM(INVOICE!D9) -> Full board
B10: DATES | C10: =TRIM(INVOICE!A9) -> Check In: 08.05.2026 Check Out: 10.05.2026
B11: ADDRESS
B12: PHONE
B18: VOUCHER NUMBER | C18: =TRIM(INVOICE!$G$1) -> INAE1352/26
B20: CLIENT NAME | C20: =TRIM(INVOICE!$B$3) -> Nina Matalasova Valeriia Polozova
B21: CITY | C21: =TRIM(INVOICE!E9) -> Manaus
B22: HOTEL | C22: =TRIM(INVOICE!B9) -> Evolucao Ecolodge
B23: CATEGORY ROOM | C23: =TRIM(INVOICE!C9) -> SGL Cahlet | D23: Qtd | E23: =TRIM(INVOICE!G9) -> 2
B24: MEAL PLAN | C24: =TRIM(INVOICE!D9) -> Full board
B25: DATES | C25: =TRIM(INVOICE!A9) -> Check In: 08.05.2026 Check Out: 10.05.2026
B26: ADDRESS
B27: PHONE
B34: VOUCHER NUMBER | C34: =TRIM(INVOICE!$G$1) -> INAE1352/26
B36: CLIENT NAME | C36: =TRIM(INVOICE!$B$3) -> Nina Matalasova Valeriia Polozova
B37: CITY | C37: =TRIM(INVOICE!E9) -> Manaus
B38: HOTEL | C38: =TRIM(INVOICE!B9) -> Evolucao Ecolodge
B39: CATEGORY ROOM | C39: =TRIM(INVOICE!C9) -> SGL Cahlet | D39: Qtd | E39: =TRIM(INVOICE!G9) -> 2
B40: MEAL PLAN | C40: =TRIM(INVOICE!D9) -> Full board
B41: DATES | C41: =TRIM(INVOICE!A9) -> Check In: 08.05.2026 Check Out: 10.05.2026
B42: ADDRESS
B43: PHONE
B49: VOUCHER NUMBER | C49: =TRIM(INVOICE!$G$1) -> INAE1352/26
B51: CLIENT NAME | C51: =TRIM(INVOICE!$B$3) -> Nina Matalasova Valeriia Polozova
B52: CITY | C52: =TRIM(INVOICE!E9) -> Manaus
B53: HOTEL | C53: =TRIM(INVOICE!B9) -> Evolucao Ecolodge
B54: CATEGORY ROOM | C54: =TRIM(INVOICE!C9) -> SGL Cahlet | D54: Qtd | E54: =TRIM(INVOICE!G9) -> 2
B55: MEAL PLAN | C55: =TRIM(INVOICE!D9) -> Full board
B56: DATES | C56: =TRIM(INVOICE!A9) -> Check In: 08.05.2026 Check Out: 10.05.2026
B57: ADDRESS
B58: PHONE
B64: VOUCHER NUMBER | C64: =TRIM(INVOICE!$G$1) -> INAE1352/26
B66: CLIENT NAME | C66: =TRIM(INVOICE!$B$3) -> Nina Matalasova Valeriia Polozova
B67: CITY | C67: =TRIM(INVOICE!E9) -> Manaus
B68: HOTEL | C68: =TRIM(INVOICE!B9) -> Evolucao Ecolodge
...

Sheet VOUCHER SERVICES
B2: VOUCHER NUMBER | C2: =TRIM(INVOICE!$G$1) -> INAE1352/26
B3: CLIENT NAME | C3: =TRIM(INVOICE!$B$3) -> Nina Matalasova Valeriia Polozova
B4: CITY | C4: =TRIM(INVOICE!$E$25) -> Manaus
B7: SERVICES
B8: =TRIM(INVOICE!A25) -> 08-10.05.2026 | C8: =TRIM(INVOICE!B25) -> Evolucao Ecolodge Pakage 3d2n included transfers and tours in group with English guide, Meeting of the waters, inc Pink dolphins swimming
B9: =TRIM(INVOICE!#REF!) -> #REF! | C9: =TRIM(INVOICE!#REF!) -> #REF!
B10: =TRIM(INVOICE!#REF!) -> #REF! | C10: =TRIM(INVOICE!#REF!) -> #REF!
B11: =TRIM(INVOICE!#REF!) -> #REF! | C11: =TRIM(INVOICE!#REF!) -> #REF!
B12: =TRIM(INVOICE!#REF!) -> #REF! | C12: =TRIM(INVOICE!#REF!) -> #REF!
B13: =TRIM(INVOICE!#REF!) -> #REF! | C13: =TRIM(INVOICE!#REF!) -> #REF!
B14: =TRIM(INVOICE!#REF!) -> #REF! | C14: =TRIM(INVOICE!#REF!) -> #REF!
B15: =TRIM(INVOICE!#REF!) -> #REF! | C15: =TRIM(INVOICE!#REF!) -> #REF!
B16: =TRIM(INVOICE!#REF!) -> #REF! | C16: =TRIM(INVOICE!#REF!) -> #REF!
B17: =TRIM(INVOICE!#REF!) -> #REF! | C17: =TRIM(INVOICE!#REF!) -> #REF!
B22: VOUCHER NUMBER | C22: =TRIM(INVOICE!$G$1) -> INAE1352/26
B23: CLIENT NAME | C23: =TRIM(INVOICE!$B$3) -> Nina Matalasova Valeriia Polozova
B24: CITY | C24: =TRIM(INVOICE!$E$25) -> Manaus
B27: SERVICES
B28: =TRIM(INVOICE!A25) -> 08-10.05.2026 | C28: =TRIM(INVOICE!B25) -> Evolucao Ecolodge Pakage 3d2n included transfers and tours in group with English guide, Meeting of the waters, inc Pink dolphins swimming
B29: =TRIM(INVOICE!#REF!) -> #REF! | C29: =TRIM(INVOICE!#REF!) -> #REF!
B30: =TRIM(INVOICE!#REF!) -> #REF! | C30: =TRIM(INVOICE!#REF!) -> #REF!
B31: =TRIM(INVOICE!#REF!) -> #REF! | C31: =TRIM(INVOICE!#REF!) -> #REF!
B32: =TRIM(INVOICE!#REF!) -> #REF! | C32: =TRIM(INVOICE!#REF!) -> #REF!
B33: =TRIM(INVOICE!#REF!) -> #REF! | C33: =TRIM(INVOICE!#REF!) -> #REF!
B34: =TRIM(INVOICE!#REF!) -> #REF! | C34: =TRIM(INVOICE!#REF!) -> #REF!
B35: =TRIM(INVOICE!#REF!) -> #REF! | C35: =TRIM(INVOICE!#REF!) -> #REF!
B36: =TRIM(INVOICE!#REF!) -> #REF! | C36: =TRIM(INVOICE!#REF!) -> #REF!
B37: =TRIM(INVOICE!#REF!) -> #REF! | C37: =TRIM(INVOICE!#REF!) -> #REF!
B38: =TRIM(INVOICE!#REF!) -> #REF! | C38: =TRIM(INVOICE!#REF!) -> #REF!
B39: =TRIM(INVOICE!#REF!) -> #REF! | C39: =TRIM(INVOICE!#REF!) -> #REF!
B40: =TRIM(INVOICE!#REF!) -> #REF! | C40: =TRIM(INVOICE!#REF!) -> #REF!
... B43: =TRIM(INVOICE!#REF!) -> #REF! | C43: =TRIM(INVOICE!#REF!) -> #REF!
B49: VOUCHER NUMBER | C49: =TRIM(INVOICE!$G$1) -> INAE1352/26
B50: CLIENT NAME | C50: =TRIM(INVOICE!$B$3) -> Nina Matalasova Valeriia Polozova
B51: CITY | C51: =TRIM(INVOICE!$E$25) -> Manaus
B54: SERVICES
B55: =TRIM(INVOICE!A25) -> 08-10.05.2026 | C55: =TRIM(INVOICE!B25) -> Evolucao Ecolodge Pakage 3d2n included transfers and tours in group with English guide, Meeting of the waters, inc Pink dolphins swimming
B56: =TRIM(INVOICE!#REF!) -> #REF! | C56: =TRIM(INVOICE!#REF!) -> #REF!
B57: =TRIM(INVOICE!#REF!) -> #REF! | C57: =TRIM(INVOICE!#REF!) -> #REF!
B58: =TRIM(INVOICE!#REF!) -> #REF! | C58: =TRIM(INVOICE!#REF!) -> #REF!
...

Sheet EXTRAS INFORMATIONS
H2: INDR0/19
F3: Operator:
B4: DADOS:
